[2025-02-17T08:01:21.564+0000] {taskinstance.py:1171} INFO - Dependencies all met for <TaskInstance: ml_pipeline.load manual__2025-02-17T08:01:08.620138+00:00 [queued]>
[2025-02-17T08:01:21.583+0000] {taskinstance.py:1171} INFO - Dependencies all met for <TaskInstance: ml_pipeline.load manual__2025-02-17T08:01:08.620138+00:00 [queued]>
[2025-02-17T08:01:21.586+0000] {taskinstance.py:1368} INFO - 
--------------------------------------------------------------------------------
[2025-02-17T08:01:21.587+0000] {taskinstance.py:1369} INFO - Starting attempt 1 of 1
[2025-02-17T08:01:21.588+0000] {taskinstance.py:1370} INFO - 
--------------------------------------------------------------------------------
[2025-02-17T08:01:21.611+0000] {taskinstance.py:1389} INFO - Executing <Task(PythonOperator): load> on 2025-02-17 08:01:08.620138+00:00
[2025-02-17T08:01:21.623+0000] {standard_task_runner.py:52} INFO - Started process 2160 to run task
[2025-02-17T08:01:21.630+0000] {standard_task_runner.py:79} INFO - Running: ['***', 'tasks', 'run', 'ml_pipeline', 'load', 'manual__2025-02-17T08:01:08.620138+00:00', '--job-id', '22', '--raw', '--subdir', 'DAGS_FOLDER/DAG-fraud.py', '--cfg-path', '/tmp/tmp88c4mblt', '--error-file', '/tmp/tmplcd_udu0']
[2025-02-17T08:01:21.632+0000] {standard_task_runner.py:80} INFO - Job 22: Subtask load
[2025-02-17T08:01:21.728+0000] {task_command.py:371} INFO - Running <TaskInstance: ml_pipeline.load manual__2025-02-17T08:01:08.620138+00:00 [running]> on host 925d9315849a
[2025-02-17T08:01:21.823+0000] {taskinstance.py:1581} INFO - Exporting the following env vars:
AIRFLOW_CTX_DAG_OWNER=group1
AIRFLOW_CTX_DAG_ID=ml_pipeline
AIRFLOW_CTX_TASK_ID=load
AIRFLOW_CTX_EXECUTION_DATE=2025-02-17T08:01:08.620138+00:00
AIRFLOW_CTX_TRY_NUMBER=1
AIRFLOW_CTX_DAG_RUN_ID=manual__2025-02-17T08:01:08.620138+00:00
[2025-02-17T08:01:21.943+0000] {base.py:68} INFO - Using connection ID 'postgres_***' for task execution.
[2025-02-17T08:01:21.954+0000] {taskinstance.py:1902} ERROR - Task failed with exception
Traceback (most recent call last):
  File "/home/airflow/.local/lib/python3.9/site-packages/airflow/operators/python.py", line 171, in execute
    return_value = self.execute_callable()
  File "/home/airflow/.local/lib/python3.9/site-packages/airflow/operators/python.py", line 189, in execute_callable
    return self.python_callable(*self.op_args, **self.op_kwargs)
  File "/opt/airflow/dags/DAG-fraud.py", line 81, in load_data
    cursor.execute(
psycopg2.ProgrammingError: can't adapt type 'numpy.int64'
[2025-02-17T08:01:21.979+0000] {taskinstance.py:1407} INFO - Marking task as FAILED. dag_id=ml_pipeline, task_id=load, execution_date=20250217T080108, start_date=20250217T080121, end_date=20250217T080121
[2025-02-17T08:01:21.999+0000] {standard_task_runner.py:92} ERROR - Failed to execute job 22 for task load (can't adapt type 'numpy.int64'; 2160)
[2025-02-17T08:01:22.043+0000] {local_task_job.py:156} INFO - Task exited with return code 1
[2025-02-17T08:01:22.088+0000] {local_task_job.py:279} INFO - 0 downstream tasks scheduled from follow-on schedule check
