[2025-02-17T06:38:27.911+0000] {taskinstance.py:1171} INFO - Dependencies all met for <TaskInstance: ml_pipeline.extract scheduled__2025-02-15T12:00:00+00:00 [queued]>
[2025-02-17T06:38:27.929+0000] {taskinstance.py:1171} INFO - Dependencies all met for <TaskInstance: ml_pipeline.extract scheduled__2025-02-15T12:00:00+00:00 [queued]>
[2025-02-17T06:38:27.930+0000] {taskinstance.py:1368} INFO - 
--------------------------------------------------------------------------------
[2025-02-17T06:38:27.930+0000] {taskinstance.py:1369} INFO - Starting attempt 1 of 1
[2025-02-17T06:38:27.931+0000] {taskinstance.py:1370} INFO - 
--------------------------------------------------------------------------------
[2025-02-17T06:38:27.976+0000] {taskinstance.py:1389} INFO - Executing <Task(PythonOperator): extract> on 2025-02-15 12:00:00+00:00
[2025-02-17T06:38:28.015+0000] {standard_task_runner.py:52} INFO - Started process 618 to run task
[2025-02-17T06:38:28.024+0000] {standard_task_runner.py:79} INFO - Running: ['***', 'tasks', 'run', 'ml_pipeline', 'extract', 'scheduled__2025-02-15T12:00:00+00:00', '--job-id', '7', '--raw', '--subdir', 'DAGS_FOLDER/DAG-fraud.py', '--cfg-path', '/tmp/tmpivowqy02', '--error-file', '/tmp/tmp4vbjscwc']
[2025-02-17T06:38:28.026+0000] {standard_task_runner.py:80} INFO - Job 7: Subtask extract
[2025-02-17T06:38:28.141+0000] {task_command.py:371} INFO - Running <TaskInstance: ml_pipeline.extract scheduled__2025-02-15T12:00:00+00:00 [running]> on host 925d9315849a
[2025-02-17T06:38:28.242+0000] {taskinstance.py:1581} INFO - Exporting the following env vars:
AIRFLOW_CTX_DAG_OWNER=group1
AIRFLOW_CTX_DAG_ID=ml_pipeline
AIRFLOW_CTX_TASK_ID=extract
AIRFLOW_CTX_EXECUTION_DATE=2025-02-15T12:00:00+00:00
AIRFLOW_CTX_TRY_NUMBER=1
AIRFLOW_CTX_DAG_RUN_ID=scheduled__2025-02-15T12:00:00+00:00
[2025-02-17T06:38:28.281+0000] {base.py:68} INFO - Using connection ID 'postgres_***' for task execution.
[2025-02-17T06:38:28.313+0000] {logging_mixin.py:115} WARNING - /home/***/.local/lib/python3.9/site-packages/pandas/io/sql.py:761 UserWarning: pandas only support SQLAlchemy connectable(engine/connection) ordatabase string URI or sqlite3 DBAPI2 connectionother DBAPI2 objects are not tested, please consider using SQLAlchemy
[2025-02-17T06:38:28.322+0000] {taskinstance.py:1902} ERROR - Task failed with exception
Traceback (most recent call last):
  File "/home/airflow/.local/lib/python3.9/site-packages/pandas/io/sql.py", line 2020, in execute
    cur.execute(*args, **kwargs)
psycopg2.errors.UndefinedTable: relation "transactions" does not exist
LINE 1: ...ig, namedest, oldbalancedest, newbalancedest FROM transactio...
                                                             ^


The above exception was the direct cause of the following exception:

Traceback (most recent call last):
  File "/home/airflow/.local/lib/python3.9/site-packages/airflow/operators/python.py", line 171, in execute
    return_value = self.execute_callable()
  File "/home/airflow/.local/lib/python3.9/site-packages/airflow/operators/python.py", line 189, in execute_callable
    return self.python_callable(*self.op_args, **self.op_kwargs)
  File "/opt/airflow/dags/DAG-fraud.py", line 36, in extract_data
    df = pd.read_sql(query, source_conn)
  File "/home/airflow/.local/lib/python3.9/site-packages/pandas/io/sql.py", line 566, in read_sql
    return pandas_sql.read_query(
  File "/home/airflow/.local/lib/python3.9/site-packages/pandas/io/sql.py", line 2080, in read_query
    cursor = self.execute(*args)
  File "/home/airflow/.local/lib/python3.9/site-packages/pandas/io/sql.py", line 2032, in execute
    raise ex from exc
pandas.io.sql.DatabaseError: Execution failed on sql 'SELECT step, type, amount, nameorig, oldbalanceorg, newbalanceorig, namedest, oldbalancedest, newbalancedest FROM transactions': relation "transactions" does not exist
LINE 1: ...ig, namedest, oldbalancedest, newbalancedest FROM transactio...
                                                             ^

[2025-02-17T06:38:28.344+0000] {taskinstance.py:1407} INFO - Marking task as FAILED. dag_id=ml_pipeline, task_id=extract, execution_date=20250215T120000, start_date=20250217T063827, end_date=20250217T063828
[2025-02-17T06:38:28.365+0000] {standard_task_runner.py:92} ERROR - Failed to execute job 7 for task extract (Execution failed on sql 'SELECT step, type, amount, nameorig, oldbalanceorg, newbalanceorig, namedest, oldbalancedest, newbalancedest FROM transactions': relation "transactions" does not exist
LINE 1: ...ig, namedest, oldbalancedest, newbalancedest FROM transactio...
                                                             ^
; 618)
[2025-02-17T06:38:28.407+0000] {local_task_job.py:156} INFO - Task exited with return code 1
[2025-02-17T06:38:28.469+0000] {local_task_job.py:279} INFO - 0 downstream tasks scheduled from follow-on schedule check
