[2025-02-17T12:33:17.697+0000] {taskinstance.py:1171} INFO - Dependencies all met for <TaskInstance: ml_pipeline.extract scheduled__2025-02-16T12:00:00+00:00 [queued]>
[2025-02-17T12:33:17.747+0000] {taskinstance.py:1171} INFO - Dependencies all met for <TaskInstance: ml_pipeline.extract scheduled__2025-02-16T12:00:00+00:00 [queued]>
[2025-02-17T12:33:17.749+0000] {taskinstance.py:1368} INFO - 
--------------------------------------------------------------------------------
[2025-02-17T12:33:17.750+0000] {taskinstance.py:1369} INFO - Starting attempt 1 of 1
[2025-02-17T12:33:17.756+0000] {taskinstance.py:1370} INFO - 
--------------------------------------------------------------------------------
[2025-02-17T12:33:17.805+0000] {taskinstance.py:1389} INFO - Executing <Task(PythonOperator): extract> on 2025-02-16 12:00:00+00:00
[2025-02-17T12:33:18.001+0000] {standard_task_runner.py:52} INFO - Started process 2993 to run task
[2025-02-17T12:33:17.988+0000] {standard_task_runner.py:79} INFO - Running: ['***', 'tasks', 'run', 'ml_pipeline', 'extract', 'scheduled__2025-02-16T12:00:00+00:00', '--job-id', '38', '--raw', '--subdir', 'DAGS_FOLDER/DAG-fraud.py', '--cfg-path', '/tmp/tmpn50d32jd', '--error-file', '/tmp/tmplpnl72f_']
[2025-02-17T12:33:18.051+0000] {standard_task_runner.py:80} INFO - Job 38: Subtask extract
[2025-02-17T12:33:18.903+0000] {task_command.py:371} INFO - Running <TaskInstance: ml_pipeline.extract scheduled__2025-02-16T12:00:00+00:00 [running]> on host 925d9315849a
[2025-02-17T12:33:19.185+0000] {taskinstance.py:1581} INFO - Exporting the following env vars:
AIRFLOW_CTX_DAG_OWNER=group1
AIRFLOW_CTX_DAG_ID=ml_pipeline
AIRFLOW_CTX_TASK_ID=extract
AIRFLOW_CTX_EXECUTION_DATE=2025-02-16T12:00:00+00:00
AIRFLOW_CTX_TRY_NUMBER=1
AIRFLOW_CTX_DAG_RUN_ID=scheduled__2025-02-16T12:00:00+00:00
[2025-02-17T12:33:19.255+0000] {base.py:68} INFO - Using connection ID 'postgres_***' for task execution.
[2025-02-17T12:33:19.365+0000] {logging_mixin.py:115} WARNING - /home/***/.local/lib/python3.9/site-packages/pandas/io/sql.py:761 UserWarning: pandas only support SQLAlchemy connectable(engine/connection) ordatabase string URI or sqlite3 DBAPI2 connectionother DBAPI2 objects are not tested, please consider using SQLAlchemy
[2025-02-17T12:33:20.931+0000] {DAG-fraud.py:41} INFO - Data extraction successful.
[2025-02-17T12:33:20.939+0000] {python.py:173} INFO - Done. Returned value was: None
[2025-02-17T12:33:20.964+0000] {taskinstance.py:1407} INFO - Marking task as SUCCESS. dag_id=ml_pipeline, task_id=extract, execution_date=20250216T120000, start_date=20250217T123317, end_date=20250217T123320
[2025-02-17T12:33:21.043+0000] {local_task_job.py:156} INFO - Task exited with return code 0
[2025-02-17T12:33:21.104+0000] {local_task_job.py:279} INFO - 1 downstream tasks scheduled from follow-on schedule check
[2025-02-17T15:28:41.634+0000] {taskinstance.py:1171} INFO - Dependencies all met for <TaskInstance: ml_pipeline.extract scheduled__2025-02-16T12:00:00+00:00 [queued]>
[2025-02-17T15:28:41.652+0000] {taskinstance.py:1171} INFO - Dependencies all met for <TaskInstance: ml_pipeline.extract scheduled__2025-02-16T12:00:00+00:00 [queued]>
[2025-02-17T15:28:41.652+0000] {taskinstance.py:1368} INFO - 
--------------------------------------------------------------------------------
[2025-02-17T15:28:41.653+0000] {taskinstance.py:1369} INFO - Starting attempt 1 of 1
[2025-02-17T15:28:41.653+0000] {taskinstance.py:1370} INFO - 
--------------------------------------------------------------------------------
[2025-02-17T15:28:41.672+0000] {taskinstance.py:1389} INFO - Executing <Task(PythonOperator): extract> on 2025-02-16 12:00:00+00:00
[2025-02-17T15:28:41.689+0000] {standard_task_runner.py:52} INFO - Started process 192 to run task
[2025-02-17T15:28:41.694+0000] {standard_task_runner.py:79} INFO - Running: ['***', 'tasks', 'run', 'ml_pipeline', 'extract', 'scheduled__2025-02-16T12:00:00+00:00', '--job-id', '5', '--raw', '--subdir', 'DAGS_FOLDER/DAG-fraud.py', '--cfg-path', '/tmp/tmpwc1u8ewm', '--error-file', '/tmp/tmp_0_2rhyh']
[2025-02-17T15:28:41.695+0000] {standard_task_runner.py:80} INFO - Job 5: Subtask extract
[2025-02-17T15:28:41.762+0000] {task_command.py:371} INFO - Running <TaskInstance: ml_pipeline.extract scheduled__2025-02-16T12:00:00+00:00 [running]> on host 8538735272b1
[2025-02-17T15:28:41.846+0000] {taskinstance.py:1581} INFO - Exporting the following env vars:
AIRFLOW_CTX_DAG_OWNER=group1
AIRFLOW_CTX_DAG_ID=ml_pipeline
AIRFLOW_CTX_TASK_ID=extract
AIRFLOW_CTX_EXECUTION_DATE=2025-02-16T12:00:00+00:00
AIRFLOW_CTX_TRY_NUMBER=1
AIRFLOW_CTX_DAG_RUN_ID=scheduled__2025-02-16T12:00:00+00:00
[2025-02-17T15:28:41.868+0000] {taskinstance.py:1902} ERROR - Task failed with exception
Traceback (most recent call last):
  File "/home/airflow/.local/lib/python3.9/site-packages/airflow/operators/python.py", line 171, in execute
    return_value = self.execute_callable()
  File "/home/airflow/.local/lib/python3.9/site-packages/airflow/operators/python.py", line 189, in execute_callable
    return self.python_callable(*self.op_args, **self.op_kwargs)
  File "/opt/airflow/dags/DAG-fraud.py", line 30, in extract_data
    source_conn = source_hook.get_conn()
  File "/home/airflow/.local/lib/python3.9/site-packages/airflow/providers/postgres/hooks/postgres.py", line 86, in get_conn
    conn = deepcopy(self.connection or self.get_connection(conn_id))
  File "/home/airflow/.local/lib/python3.9/site-packages/airflow/hooks/base.py", line 67, in get_connection
    conn = Connection.get_connection_from_secrets(conn_id)
  File "/home/airflow/.local/lib/python3.9/site-packages/airflow/models/connection.py", line 430, in get_connection_from_secrets
    raise AirflowNotFoundException(f"The conn_id `{conn_id}` isn't defined")
airflow.exceptions.AirflowNotFoundException: The conn_id `postgres_***` isn't defined
[2025-02-17T15:28:41.878+0000] {taskinstance.py:1407} INFO - Marking task as FAILED. dag_id=ml_pipeline, task_id=extract, execution_date=20250216T120000, start_date=20250217T152841, end_date=20250217T152841
[2025-02-17T15:28:41.895+0000] {standard_task_runner.py:92} ERROR - Failed to execute job 5 for task extract (The conn_id `postgres_***` isn't defined; 192)
[2025-02-17T15:28:41.907+0000] {local_task_job.py:156} INFO - Task exited with return code 1
[2025-02-17T15:28:41.959+0000] {local_task_job.py:279} INFO - 0 downstream tasks scheduled from follow-on schedule check
