[2025-02-17T15:29:32.082+0000] {taskinstance.py:1171} INFO - Dependencies all met for <TaskInstance: ml_pipeline.extract manual__2025-02-17T15:29:29.934738+00:00 [queued]>
[2025-02-17T15:29:32.095+0000] {taskinstance.py:1171} INFO - Dependencies all met for <TaskInstance: ml_pipeline.extract manual__2025-02-17T15:29:29.934738+00:00 [queued]>
[2025-02-17T15:29:32.095+0000] {taskinstance.py:1368} INFO - 
--------------------------------------------------------------------------------
[2025-02-17T15:29:32.096+0000] {taskinstance.py:1369} INFO - Starting attempt 1 of 1
[2025-02-17T15:29:32.096+0000] {taskinstance.py:1370} INFO - 
--------------------------------------------------------------------------------
[2025-02-17T15:29:32.111+0000] {taskinstance.py:1389} INFO - Executing <Task(PythonOperator): extract> on 2025-02-17 15:29:29.934738+00:00
[2025-02-17T15:29:32.120+0000] {standard_task_runner.py:52} INFO - Started process 223 to run task
[2025-02-17T15:29:32.121+0000] {standard_task_runner.py:79} INFO - Running: ['***', 'tasks', 'run', 'ml_pipeline', 'extract', 'manual__2025-02-17T15:29:29.934738+00:00', '--job-id', '8', '--raw', '--subdir', 'DAGS_FOLDER/DAG-fraud.py', '--cfg-path', '/tmp/tmpwikw6y6b', '--error-file', '/tmp/tmplf9d25a4']
[2025-02-17T15:29:32.124+0000] {standard_task_runner.py:80} INFO - Job 8: Subtask extract
[2025-02-17T15:29:32.202+0000] {task_command.py:371} INFO - Running <TaskInstance: ml_pipeline.extract manual__2025-02-17T15:29:29.934738+00:00 [running]> on host 8538735272b1
[2025-02-17T15:29:32.270+0000] {taskinstance.py:1581} INFO - Exporting the following env vars:
AIRFLOW_CTX_DAG_OWNER=group1
AIRFLOW_CTX_DAG_ID=ml_pipeline
AIRFLOW_CTX_TASK_ID=extract
AIRFLOW_CTX_EXECUTION_DATE=2025-02-17T15:29:29.934738+00:00
AIRFLOW_CTX_TRY_NUMBER=1
AIRFLOW_CTX_DAG_RUN_ID=manual__2025-02-17T15:29:29.934738+00:00
[2025-02-17T15:29:32.282+0000] {base.py:68} INFO - Using connection ID 'postgres_***' for task execution.
[2025-02-17T15:29:32.294+0000] {logging_mixin.py:115} WARNING - /home/***/.local/lib/python3.9/site-packages/pandas/io/sql.py:761 UserWarning: pandas only support SQLAlchemy connectable(engine/connection) ordatabase string URI or sqlite3 DBAPI2 connectionother DBAPI2 objects are not tested, please consider using SQLAlchemy
[2025-02-17T15:29:32.300+0000] {taskinstance.py:1902} ERROR - Task failed with exception
Traceback (most recent call last):
  File "/home/airflow/.local/lib/python3.9/site-packages/pandas/io/sql.py", line 2020, in execute
    cur.execute(*args, **kwargs)
psycopg2.errors.UndefinedTable: relation "transactions" does not exist
LINE 1: SELECT * FROM transactions
                      ^


The above exception was the direct cause of the following exception:

Traceback (most recent call last):
  File "/home/airflow/.local/lib/python3.9/site-packages/airflow/operators/python.py", line 171, in execute
    return_value = self.execute_callable()
  File "/home/airflow/.local/lib/python3.9/site-packages/airflow/operators/python.py", line 189, in execute_callable
    return self.python_callable(*self.op_args, **self.op_kwargs)
  File "/opt/airflow/dags/DAG-fraud.py", line 33, in extract_data
    df = pd.read_sql(query, source_conn)
  File "/home/airflow/.local/lib/python3.9/site-packages/pandas/io/sql.py", line 566, in read_sql
    return pandas_sql.read_query(
  File "/home/airflow/.local/lib/python3.9/site-packages/pandas/io/sql.py", line 2080, in read_query
    cursor = self.execute(*args)
  File "/home/airflow/.local/lib/python3.9/site-packages/pandas/io/sql.py", line 2032, in execute
    raise ex from exc
pandas.io.sql.DatabaseError: Execution failed on sql 'SELECT * FROM transactions': relation "transactions" does not exist
LINE 1: SELECT * FROM transactions
                      ^

[2025-02-17T15:29:32.316+0000] {taskinstance.py:1407} INFO - Marking task as FAILED. dag_id=ml_pipeline, task_id=extract, execution_date=20250217T152929, start_date=20250217T152932, end_date=20250217T152932
[2025-02-17T15:29:32.329+0000] {standard_task_runner.py:92} ERROR - Failed to execute job 8 for task extract (Execution failed on sql 'SELECT * FROM transactions': relation "transactions" does not exist
LINE 1: SELECT * FROM transactions
                      ^
; 223)
[2025-02-17T15:29:32.339+0000] {local_task_job.py:156} INFO - Task exited with return code 1
[2025-02-17T15:29:32.383+0000] {local_task_job.py:279} INFO - 0 downstream tasks scheduled from follow-on schedule check
