[2025-02-17T07:34:22.040+0000] {taskinstance.py:1171} INFO - Dependencies all met for <TaskInstance: ml_pipeline.predict manual__2025-02-17T07:34:13.027122+00:00 [queued]>
[2025-02-17T07:34:22.071+0000] {taskinstance.py:1171} INFO - Dependencies all met for <TaskInstance: ml_pipeline.predict manual__2025-02-17T07:34:13.027122+00:00 [queued]>
[2025-02-17T07:34:22.073+0000] {taskinstance.py:1368} INFO - 
--------------------------------------------------------------------------------
[2025-02-17T07:34:22.074+0000] {taskinstance.py:1369} INFO - Starting attempt 1 of 1
[2025-02-17T07:34:22.075+0000] {taskinstance.py:1370} INFO - 
--------------------------------------------------------------------------------
[2025-02-17T07:34:22.102+0000] {taskinstance.py:1389} INFO - Executing <Task(PythonOperator): predict> on 2025-02-17 07:34:13.027122+00:00
[2025-02-17T07:34:22.118+0000] {standard_task_runner.py:52} INFO - Started process 1411 to run task
[2025-02-17T07:34:22.121+0000] {standard_task_runner.py:79} INFO - Running: ['***', 'tasks', 'run', 'ml_pipeline', 'predict', 'manual__2025-02-17T07:34:13.027122+00:00', '--job-id', '13', '--raw', '--subdir', 'DAGS_FOLDER/DAG-fraud.py', '--cfg-path', '/tmp/tmpd_c1r2t5', '--error-file', '/tmp/tmpandqi74p']
[2025-02-17T07:34:22.124+0000] {standard_task_runner.py:80} INFO - Job 13: Subtask predict
[2025-02-17T07:34:22.234+0000] {task_command.py:371} INFO - Running <TaskInstance: ml_pipeline.predict manual__2025-02-17T07:34:13.027122+00:00 [running]> on host 925d9315849a
[2025-02-17T07:34:22.351+0000] {taskinstance.py:1581} INFO - Exporting the following env vars:
AIRFLOW_CTX_DAG_OWNER=group1
AIRFLOW_CTX_DAG_ID=ml_pipeline
AIRFLOW_CTX_TASK_ID=predict
AIRFLOW_CTX_EXECUTION_DATE=2025-02-17T07:34:13.027122+00:00
AIRFLOW_CTX_TRY_NUMBER=1
AIRFLOW_CTX_DAG_RUN_ID=manual__2025-02-17T07:34:13.027122+00:00
[2025-02-17T07:34:22.632+0000] {taskinstance.py:1902} ERROR - Task failed with exception
Traceback (most recent call last):
  File "/home/airflow/.local/lib/python3.9/site-packages/airflow/operators/python.py", line 171, in execute
    return_value = self.execute_callable()
  File "/home/airflow/.local/lib/python3.9/site-packages/airflow/operators/python.py", line 189, in execute_callable
    return self.python_callable(*self.op_args, **self.op_kwargs)
  File "/opt/airflow/dags/DAG-fraud.py", line 64, in predict_data
    df['prediction'] = model.predict(df[features])
  File "/home/airflow/.local/lib/python3.9/site-packages/pandas/core/frame.py", line 3511, in __getitem__
    indexer = self.columns._get_indexer_strict(key, "columns")[1]
  File "/home/airflow/.local/lib/python3.9/site-packages/pandas/core/indexes/base.py", line 5782, in _get_indexer_strict
    self._raise_if_missing(keyarr, indexer, axis_name)
  File "/home/airflow/.local/lib/python3.9/site-packages/pandas/core/indexes/base.py", line 5845, in _raise_if_missing
    raise KeyError(f"{not_found} not in index")
KeyError: "['old_balance_org', 'new_balance_orig', 'old_balance_dest', 'new_balance_dest'] not in index"
[2025-02-17T07:34:22.652+0000] {taskinstance.py:1407} INFO - Marking task as FAILED. dag_id=ml_pipeline, task_id=predict, execution_date=20250217T073413, start_date=20250217T073422, end_date=20250217T073422
[2025-02-17T07:34:22.674+0000] {standard_task_runner.py:92} ERROR - Failed to execute job 13 for task predict ("['old_balance_org', 'new_balance_orig', 'old_balance_dest', 'new_balance_dest'] not in index"; 1411)
[2025-02-17T07:34:22.698+0000] {local_task_job.py:156} INFO - Task exited with return code 1
[2025-02-17T07:34:22.742+0000] {local_task_job.py:279} INFO - 0 downstream tasks scheduled from follow-on schedule check
