[2025-02-17T08:04:24.340+0000] {taskinstance.py:1171} INFO - Dependencies all met for <TaskInstance: ml_pipeline.load manual__2025-02-17T08:04:12.438979+00:00 [queued]>
[2025-02-17T08:04:24.356+0000] {taskinstance.py:1171} INFO - Dependencies all met for <TaskInstance: ml_pipeline.load manual__2025-02-17T08:04:12.438979+00:00 [queued]>
[2025-02-17T08:04:24.357+0000] {taskinstance.py:1368} INFO - 
--------------------------------------------------------------------------------
[2025-02-17T08:04:24.357+0000] {taskinstance.py:1369} INFO - Starting attempt 1 of 1
[2025-02-17T08:04:24.358+0000] {taskinstance.py:1370} INFO - 
--------------------------------------------------------------------------------
[2025-02-17T08:04:24.380+0000] {taskinstance.py:1389} INFO - Executing <Task(PythonOperator): load> on 2025-02-17 08:04:12.438979+00:00
[2025-02-17T08:04:24.389+0000] {standard_task_runner.py:52} INFO - Started process 2241 to run task
[2025-02-17T08:04:24.393+0000] {standard_task_runner.py:79} INFO - Running: ['***', 'tasks', 'run', 'ml_pipeline', 'load', 'manual__2025-02-17T08:04:12.438979+00:00', '--job-id', '25', '--raw', '--subdir', 'DAGS_FOLDER/DAG-fraud.py', '--cfg-path', '/tmp/tmpdodm5npt', '--error-file', '/tmp/tmpmvc6r463']
[2025-02-17T08:04:24.396+0000] {standard_task_runner.py:80} INFO - Job 25: Subtask load
[2025-02-17T08:04:24.480+0000] {task_command.py:371} INFO - Running <TaskInstance: ml_pipeline.load manual__2025-02-17T08:04:12.438979+00:00 [running]> on host 925d9315849a
[2025-02-17T08:04:24.577+0000] {taskinstance.py:1581} INFO - Exporting the following env vars:
AIRFLOW_CTX_DAG_OWNER=group1
AIRFLOW_CTX_DAG_ID=ml_pipeline
AIRFLOW_CTX_TASK_ID=load
AIRFLOW_CTX_EXECUTION_DATE=2025-02-17T08:04:12.438979+00:00
AIRFLOW_CTX_TRY_NUMBER=1
AIRFLOW_CTX_DAG_RUN_ID=manual__2025-02-17T08:04:12.438979+00:00
[2025-02-17T08:04:24.675+0000] {base.py:68} INFO - Using connection ID 'postgres_***' for task execution.
[2025-02-17T08:04:24.685+0000] {taskinstance.py:1902} ERROR - Task failed with exception
Traceback (most recent call last):
  File "/home/airflow/.local/lib/python3.9/site-packages/airflow/operators/python.py", line 171, in execute
    return_value = self.execute_callable()
  File "/home/airflow/.local/lib/python3.9/site-packages/airflow/operators/python.py", line 189, in execute_callable
    return self.python_callable(*self.op_args, **self.op_kwargs)
  File "/opt/airflow/dags/DAG-fraud.py", line 85, in load_data
    cursor.execute(
psycopg2.ProgrammingError: can't adapt type 'numpy.int64'
[2025-02-17T08:04:24.703+0000] {taskinstance.py:1407} INFO - Marking task as FAILED. dag_id=ml_pipeline, task_id=load, execution_date=20250217T080412, start_date=20250217T080424, end_date=20250217T080424
[2025-02-17T08:04:24.723+0000] {standard_task_runner.py:92} ERROR - Failed to execute job 25 for task load (can't adapt type 'numpy.int64'; 2241)
[2025-02-17T08:04:24.770+0000] {local_task_job.py:156} INFO - Task exited with return code 1
[2025-02-17T08:04:24.813+0000] {local_task_job.py:279} INFO - 0 downstream tasks scheduled from follow-on schedule check
