[2025-02-17T08:07:18.526+0000] {taskinstance.py:1171} INFO - Dependencies all met for <TaskInstance: ml_pipeline.load manual__2025-02-17T08:07:06.604515+00:00 [queued]>
[2025-02-17T08:07:18.543+0000] {taskinstance.py:1171} INFO - Dependencies all met for <TaskInstance: ml_pipeline.load manual__2025-02-17T08:07:06.604515+00:00 [queued]>
[2025-02-17T08:07:18.544+0000] {taskinstance.py:1368} INFO - 
--------------------------------------------------------------------------------
[2025-02-17T08:07:18.545+0000] {taskinstance.py:1369} INFO - Starting attempt 1 of 1
[2025-02-17T08:07:18.545+0000] {taskinstance.py:1370} INFO - 
--------------------------------------------------------------------------------
[2025-02-17T08:07:18.566+0000] {taskinstance.py:1389} INFO - Executing <Task(PythonOperator): load> on 2025-02-17 08:07:06.604515+00:00
[2025-02-17T08:07:18.578+0000] {standard_task_runner.py:52} INFO - Started process 2313 to run task
[2025-02-17T08:07:18.581+0000] {standard_task_runner.py:79} INFO - Running: ['***', 'tasks', 'run', 'ml_pipeline', 'load', 'manual__2025-02-17T08:07:06.604515+00:00', '--job-id', '28', '--raw', '--subdir', 'DAGS_FOLDER/DAG-fraud.py', '--cfg-path', '/tmp/tmp1y1ujad8', '--error-file', '/tmp/tmp6kz3nx5c']
[2025-02-17T08:07:18.582+0000] {standard_task_runner.py:80} INFO - Job 28: Subtask load
[2025-02-17T08:07:18.667+0000] {task_command.py:371} INFO - Running <TaskInstance: ml_pipeline.load manual__2025-02-17T08:07:06.604515+00:00 [running]> on host 925d9315849a
[2025-02-17T08:07:18.764+0000] {taskinstance.py:1581} INFO - Exporting the following env vars:
AIRFLOW_CTX_DAG_OWNER=group1
AIRFLOW_CTX_DAG_ID=ml_pipeline
AIRFLOW_CTX_TASK_ID=load
AIRFLOW_CTX_EXECUTION_DATE=2025-02-17T08:07:06.604515+00:00
AIRFLOW_CTX_TRY_NUMBER=1
AIRFLOW_CTX_DAG_RUN_ID=manual__2025-02-17T08:07:06.604515+00:00
[2025-02-17T08:07:18.863+0000] {base.py:68} INFO - Using connection ID 'postgres_***' for task execution.
[2025-02-17T08:07:18.872+0000] {taskinstance.py:1902} ERROR - Task failed with exception
Traceback (most recent call last):
  File "/home/airflow/.local/lib/python3.9/site-packages/airflow/operators/python.py", line 171, in execute
    return_value = self.execute_callable()
  File "/home/airflow/.local/lib/python3.9/site-packages/airflow/operators/python.py", line 189, in execute_callable
    return self.python_callable(*self.op_args, **self.op_kwargs)
  File "/opt/airflow/dags/DAG-fraud.py", line 86, in load_data
    cursor.execute(
psycopg2.errors.InvalidColumnReference: there is no unique or exclusion constraint matching the ON CONFLICT specification

[2025-02-17T08:07:18.893+0000] {taskinstance.py:1407} INFO - Marking task as FAILED. dag_id=ml_pipeline, task_id=load, execution_date=20250217T080706, start_date=20250217T080718, end_date=20250217T080718
[2025-02-17T08:07:18.914+0000] {standard_task_runner.py:92} ERROR - Failed to execute job 28 for task load (there is no unique or exclusion constraint matching the ON CONFLICT specification
; 2313)
[2025-02-17T08:07:18.958+0000] {local_task_job.py:156} INFO - Task exited with return code 1
[2025-02-17T08:07:19.004+0000] {local_task_job.py:279} INFO - 0 downstream tasks scheduled from follow-on schedule check
