[2025-02-17T15:28:44.823+0000] {taskinstance.py:1171} INFO - Dependencies all met for <TaskInstance: ml_pipeline.extract manual__2025-02-17T15:28:42.962922+00:00 [queued]>
[2025-02-17T15:28:44.835+0000] {taskinstance.py:1171} INFO - Dependencies all met for <TaskInstance: ml_pipeline.extract manual__2025-02-17T15:28:42.962922+00:00 [queued]>
[2025-02-17T15:28:44.835+0000] {taskinstance.py:1368} INFO - 
--------------------------------------------------------------------------------
[2025-02-17T15:28:44.835+0000] {taskinstance.py:1369} INFO - Starting attempt 1 of 1
[2025-02-17T15:28:44.836+0000] {taskinstance.py:1370} INFO - 
--------------------------------------------------------------------------------
[2025-02-17T15:28:44.850+0000] {taskinstance.py:1389} INFO - Executing <Task(PythonOperator): extract> on 2025-02-17 15:28:42.962922+00:00
[2025-02-17T15:28:44.860+0000] {standard_task_runner.py:52} INFO - Started process 206 to run task
[2025-02-17T15:28:44.864+0000] {standard_task_runner.py:79} INFO - Running: ['***', 'tasks', 'run', 'ml_pipeline', 'extract', 'manual__2025-02-17T15:28:42.962922+00:00', '--job-id', '7', '--raw', '--subdir', 'DAGS_FOLDER/DAG-fraud.py', '--cfg-path', '/tmp/tmpx1rey3_a', '--error-file', '/tmp/tmpgv1oms3i']
[2025-02-17T15:28:44.865+0000] {standard_task_runner.py:80} INFO - Job 7: Subtask extract
[2025-02-17T15:28:44.930+0000] {task_command.py:371} INFO - Running <TaskInstance: ml_pipeline.extract manual__2025-02-17T15:28:42.962922+00:00 [running]> on host 8538735272b1
[2025-02-17T15:28:44.992+0000] {taskinstance.py:1581} INFO - Exporting the following env vars:
AIRFLOW_CTX_DAG_OWNER=group1
AIRFLOW_CTX_DAG_ID=ml_pipeline
AIRFLOW_CTX_TASK_ID=extract
AIRFLOW_CTX_EXECUTION_DATE=2025-02-17T15:28:42.962922+00:00
AIRFLOW_CTX_TRY_NUMBER=1
AIRFLOW_CTX_DAG_RUN_ID=manual__2025-02-17T15:28:42.962922+00:00
[2025-02-17T15:28:45.011+0000] {taskinstance.py:1902} ERROR - Task failed with exception
Traceback (most recent call last):
  File "/home/airflow/.local/lib/python3.9/site-packages/airflow/operators/python.py", line 171, in execute
    return_value = self.execute_callable()
  File "/home/airflow/.local/lib/python3.9/site-packages/airflow/operators/python.py", line 189, in execute_callable
    return self.python_callable(*self.op_args, **self.op_kwargs)
  File "/opt/airflow/dags/DAG-fraud.py", line 30, in extract_data
    source_conn = source_hook.get_conn()
  File "/home/airflow/.local/lib/python3.9/site-packages/airflow/providers/postgres/hooks/postgres.py", line 86, in get_conn
    conn = deepcopy(self.connection or self.get_connection(conn_id))
  File "/home/airflow/.local/lib/python3.9/site-packages/airflow/hooks/base.py", line 67, in get_connection
    conn = Connection.get_connection_from_secrets(conn_id)
  File "/home/airflow/.local/lib/python3.9/site-packages/airflow/models/connection.py", line 430, in get_connection_from_secrets
    raise AirflowNotFoundException(f"The conn_id `{conn_id}` isn't defined")
airflow.exceptions.AirflowNotFoundException: The conn_id `postgres_***` isn't defined
[2025-02-17T15:28:45.018+0000] {taskinstance.py:1407} INFO - Marking task as FAILED. dag_id=ml_pipeline, task_id=extract, execution_date=20250217T152842, start_date=20250217T152844, end_date=20250217T152845
[2025-02-17T15:28:45.030+0000] {standard_task_runner.py:92} ERROR - Failed to execute job 7 for task extract (The conn_id `postgres_***` isn't defined; 206)
[2025-02-17T15:28:45.076+0000] {local_task_job.py:156} INFO - Task exited with return code 1
[2025-02-17T15:28:45.115+0000] {local_task_job.py:279} INFO - 0 downstream tasks scheduled from follow-on schedule check
